Workbook

Sheet Summary
A1: Layout | B1: Layout Type | C1: Date | D1: Vol 12 AM | E1: Vol 1 AM | F1: Vol 2 AM | G1: Vol 3 AM | H1: Vol 4 AM | I1: Vol 5 AM | J1: Vol 6 AM | K1: Vol 7 AM | L1: Vol 8 AM | M1: Vol 9 AM | N1: Vol 10 AM | O1: Vol 11 AM | P1: Vol 12 PM | Q1: Vol 1 PM | R1: Vol 2 PM | S1: Vol 3 PM | T1: Vol 4 PM | U1: Vol 5 PM | V1: Vol 6 PM | W1: Vol 7 PM | X1: Vol 8 PM | Y1: Vol 9 PM | Z1: Vol 10 PM | AA1: Vol 11 PM | AB1: Vol Total | AD1: MH 12 AM | AE1: MH 1 AM | AF1: MH 2 AM | AG1: MH 3 AM | AH1: MH 4 AM | AI1: MH 5 AM | AJ1: MH 6 AM | AK1: MH 7 AM | AL1: MH 8 AM | AM1: MH 9 AM | AN1: MH 10 AM | AO1: MH 11 AM | AP1: MH 12 PM | AQ1: MH 1 PM | AR1: MH 2 PM | AS1: MH 3 PM | AT1: MH 4 PM | AU1: MH 5 PM | AV1: MH 6 PM | AW1: MH 7 PM | AX1: MH 8 PM | AY1: MH 9 PM | AZ1: MH 10 PM | BA1: MH 11 PM | BB1: MH Total
A2: AMD-AIR-NEW-SSC | B2: Forward Regular OSC | C2: 46093 | D2: 0 | E2: 0 | F2: 0 | G2: 0 | H2: 0 | I2: 0 | J2: 0 | K2: 0 | L2: 0 | M2: 0 | N2: 0 | O2: 0 | P2: 0 | Q2: 0 | R2: 406 | S2: 389 | T2: 0 | U2: 0 | V2: 0 | W2: 0 | X2: 0 | Y2: 0 | Z2: 0 | AA2: 0 | AB2: =SUM(D2:AA2) | AD2: ='BBB'!AD2+'Bag Staging'!AD2+'Bag Staging Volumetric'!AD2+'FWD FSM'!AD2+'FWD Manual Pre Primary'!AD2+'FWD Manual Primary'!AD2+'FWD Primary with Scan'!AD2+'FWD Secondary'!AD2+'FWD Volumetric'!AD2+'IB'!AD2+'IB Volumetric'!AD2+'OB'!AD2+'OB Volumetric'!AD2+'OSC Bag Sorting'!AD2+'OSC Bag Sorting Volumetric'!AD2+'REV FSM'!AD2+'Rejection Primary with Scan'!AD2+'Rejection Secondary'!AD2+'Rev DC DC Primary Sorting'!AD2+'Rev Primary (FSM Rejections)'!AD2+'Rev Secondary Sorting'!AD2+'VIA Bag Sorting'!AD2 | AE2: ='BBB'!AE2+'Bag Staging'!AE2+'Bag Staging Volumetric'!AE2+'FWD FSM'!AE2+'FWD Manual Pre Primary'!AE2+'FWD Manual Primary'!AE2+'FWD Primary with Scan'!AE2+'FWD Secondary'!AE2+'FWD Volumetric'!AE2+'IB'!AE2+'IB Volumetric'!AE2+'OB'!AE2+'OB Volumetric'!AE2+'OSC Bag Sorting'!AE2+'OSC Bag Sorting Volumetric'!AE2+'REV FSM'!AE2+'Rejection Primary with Scan'!AE2+'Rejection Secondary'!AE2+'Rev DC DC Primary Sorting'!AE2+'Rev Primary (FSM Rejections)'!AE2+'Rev Secondary Sorting'!AE2+'VIA Bag Sorting'!AE2 | AF2: ='BBB'!AF2+'Bag Staging'!AF2+'Bag Staging Volumetric'!AF2+'FWD FSM'!AF2+'FWD Manual Pre Primary'!AF2+'FWD Manual Primary'!AF2+'FWD Primary with Scan'!AF2+'FWD Secondary'!AF2+'FWD Volumetric'!AF2+'IB'!AF2+'IB Volumetric'!AF2+'OB'!AF2+'OB Volumetric'!AF2+'OSC Bag Sorting'!AF2+'OSC Bag Sorting Volumetric'!AF2+'REV FSM'!AF2+'Rejection Primary with Scan'!AF2+'Rejection Secondary'!AF2+'Rev DC DC Primary Sorting'!AF2+'Rev Primary (FSM Rejections)'!AF2+'Rev Secondary Sorting'!AF2+'VIA Bag Sorting'!AF2 | AG2: ='BBB'!AG2+'Bag Staging'!AG2+'Bag Staging Volumetric'!AG2+'FWD FSM'!AG2+'FWD Manual Pre Primary'!AG2+'FWD Manual Primary'!AG2+'FWD Primary with Scan'!AG2+'FWD Secondary'!AG2+'FWD Volumetric'!AG2+'IB'!AG2+'IB Volumetric'!AG2+'OB'!AG2+'OB Volumetric'!AG2+'OSC Bag Sorting'!AG2+'OSC Bag Sorting Volumetric'!AG2+'REV FSM'!AG2+'Rejection Primary with Scan'!AG2+'Rejection Secondary'!AG2+'Rev DC DC Primary Sorting'!AG2+'Rev Primary (FSM Rejections)'!AG2+'Rev Secondary Sorting'!AG2+'VIA Bag Sorting'!AG2 | AH2: ='BBB'!AH2+'Bag Staging'!AH2+'Bag Staging Volumetric'!AH2+'FWD FSM'!AH2+'FWD Manual Pre Primary'!AH2+'FWD Manual Primary'!AH2+'FWD Primary with Scan'!AH2+'FWD Secondary'!AH2+'FWD Volumetric'!AH2+'IB'!AH2+'IB Volumetric'!AH2+'OB'!AH2+'OB Volumetric'!AH2+'OSC Bag Sorting'!AH2+'OSC Bag Sorting Volumetric'!AH2+'REV FSM'!AH2+'Rejection Primary with Scan'!AH2+'Rejection Secondary'!AH2+'Rev DC DC Primary Sorting'!AH2+'Rev Primary (FSM Rejections)'!AH2+'Rev Secondary Sorting'!AH2+'VIA Bag Sorting'!AH2 | AI2: ='BBB'!AI2+'Bag Staging'!AI2+'Bag Staging Volumetric'!AI2+'FWD FSM'!AI2+'FWD Manual Pre Primary'!AI2+'FWD Manual Primary'!AI2+'FWD Primary with Scan'!AI2+'FWD Secondary'!AI2+'FWD Volumetric'!AI2+'IB'!AI2+'IB Volumetric'!AI2+'OB'!AI2+'OB Volumetric'!AI2+'OSC Bag Sorting'!AI2+'OSC Bag Sorting Volumetric'!AI2+'REV FSM'!AI2+'Rejection Primary with Scan'!AI2+'Rejection Secondary'!AI2+'Rev DC DC Primary Sorting'!AI2+'Rev Primary (FSM Rejections)'!AI2+'Rev Secondary Sorting'!AI2+'VIA Bag Sorting'!AI2 | AJ2: ='BBB'!AJ2+'Bag Staging'!AJ2+'Bag Staging Volumetric'!AJ2+'FWD FSM'!AJ2+'FWD Manual Pre Primary'!AJ2+'FWD Manual Primary'!AJ2+'FWD Primary with Scan'!AJ2+'FWD Secondary'!AJ2+'FWD Volumetric'!AJ2+'IB'!AJ2+'IB Volumetric'!AJ2+'OB'!AJ2+'OB Volumetric'!AJ2+'OSC Bag Sorting'!AJ2+'OSC Bag Sorting Volumetric'!AJ2+'REV FSM'!AJ2+'Rejection Primary with Scan'!AJ2+'Rejection Secondary'!AJ2+'Rev DC DC Primary Sorting'!AJ2+'Rev Primary (FSM Rejections)'!AJ2+'Rev Secondary Sorting'!AJ2+'VIA Bag Sorting'!AJ2 | AK2: ='BBB'!AK2+'Bag Staging'!AK2+'Bag Staging Volumetric'!AK2+'FWD FSM'!AK2+'FWD Manual Pre Primary'!AK2+'FWD Manual Primary'!AK2+'FWD Primary with Scan'!AK2+'FWD Secondary'!AK2+'FWD Volumetric'!AK2+'IB'!AK2+'IB Volumetric'!AK2+'OB'!AK2+'OB Volumetric'!AK2+'OSC Bag Sorting'!AK2+'OSC Bag Sorting Volumetric'!AK2+'REV FSM'!AK2+'Rejection Primary with Scan'!AK2+'Rejection Secondary'!AK2+'Rev DC DC Primary Sorting'!AK2+'Rev Primary (FSM Rejections)'!AK2+'Rev Secondary Sorting'!AK2+'VIA Bag Sorting'!AK2 | ... BA2: ='BBB'!BA2+'Bag Staging'!BA2+'Bag Staging Volumetric'!BA2+'FWD FSM'!BA2+'FWD Manual Pre Primary'!BA2+'FWD Manual Primary'!BA2+'FWD Primary with Scan'!BA2+'FWD Secondary'!BA2+'FWD Volumetric'!BA2+'IB'!BA2+'IB Volumetric'!BA2+'OB'!BA2+'OB Volumetric'!BA2+'OSC Bag Sorting'!BA2+'OSC Bag Sorting Volumetric'!BA2+'REV FSM'!BA2+'Rejection Primary with Scan'!BA2+'Rejection Secondary'!BA2+'Rev DC DC Primary Sorting'!BA2+'Rev Primary (FSM Rejections)'!BA2+'Rev Secondary Sorting'!BA2+'VIA Bag Sorting'!BA2 | BB2: =SUM(AD2:BA2)
A3: AMD-AIR-NEW-SSC | B3: Forward Regular OSC | C3: 46094 | D3: 0 | E3: 0 | F3: 0 | G3: 0 | H3: 0 | I3: 0 | J3: 0 | K3: 0 | L3: 0 | M3: 0 | N3: 0 | O3: 0 | P3: 0 | Q3: 0 | R3: 0 | S3: 592 | T3: 2 | U3: 0 | V3: 0 | W3: 0 | X3: 0 | Y3: 0 | Z3: 0 | AA3: 0 | AB3: =SUM(D3:AA3) | AD3: ='BBB'!AD3+'Bag Staging'!AD3+'Bag Staging Volumetric'!AD3+'FWD FSM'!AD3+'FWD Manual Pre Primary'!AD3+'FWD Manual Primary'!AD3+'FWD Primary with Scan'!AD3+'FWD Secondary'!AD3+'FWD Volumetric'!AD3+'IB'!AD3+'IB Volumetric'!AD3+'OB'!AD3+'OB Volumetric'!AD3+'OSC Bag Sorting'!AD3+'OSC Bag Sorting Volumetric'!AD3+'REV FSM'!AD3+'Rejection Primary with Scan'!AD3+'Rejection Secondary'!AD3+'Rev DC DC Primary Sorting'!AD3+'Rev Primary (FSM Rejections)'!AD3+'Rev Secondary Sorting'!AD3+'VIA Bag Sorting'!AD3 | AE3: ='BBB'!AE3+'Bag Staging'!AE3+'Bag Staging Volumetric'!AE3+'FWD FSM'!AE3+'FWD Manual Pre Primary'!AE3+'FWD Manual Primary'!AE3+'FWD Primary with Scan'!AE3+'FWD Secondary'!AE3+'FWD Volumetric'!AE3+'IB'!AE3+'IB Volumetric'!AE3+'OB'!AE3+'OB Volumetric'!AE3+'OSC Bag Sorting'!AE3+'OSC Bag Sorting Volumetric'!AE3+'REV FSM'!AE3+'Rejection Primary with Scan'!AE3+'Rejection Secondary'!AE3+'Rev DC DC Primary Sorting'!AE3+'Rev Primary (FSM Rejections)'!AE3+'Rev Secondary Sorting'!AE3+'VIA Bag Sorting'!AE3 | AF3: ='BBB'!AF3+'Bag Staging'!AF3+'Bag Staging Volumetric'!AF3+'FWD FSM'!AF3+'FWD Manual Pre Primary'!AF3+'FWD Manual Primary'!AF3+'FWD Primary with Scan'!AF3+'FWD Secondary'!AF3+'FWD Volumetric'!AF3+'IB'!AF3+'IB Volumetric'!AF3+'OB'!AF3+'OB Volumetric'!AF3+'OSC Bag Sorting'!AF3+'OSC Bag Sorting Volumetric'!AF3+'REV FSM'!AF3+'Rejection Primary with Scan'!AF3+'Rejection Secondary'!AF3+'Rev DC DC Primary Sorting'!AF3+'Rev Primary (FSM Rejections)'!AF3+'Rev Secondary Sorting'!AF3+'VIA Bag Sorting'!AF3 | AG3: ='BBB'!AG3+'Bag Staging'!AG3+'Bag Staging Volumetric'!AG3+'FWD FSM'!AG3+'FWD Manual Pre Primary'!AG3+'FWD Manual Primary'!AG3+'FWD Primary with Scan'!AG3+'FWD Secondary'!AG3+'FWD Volumetric'!AG3+'IB'!AG3+'IB Volumetric'!AG3+'OB'!AG3+'OB Volumetric'!AG3+'OSC Bag Sorting'!AG3+'OSC Bag Sorting Volumetric'!AG3+'REV FSM'!AG3+'Rejection Primary with Scan'!AG3+'Rejection Secondary'!AG3+'Rev DC DC Primary Sorting'!AG3+'Rev Primary (FSM Rejections)'!AG3+'Rev Secondary Sorting'!AG3+'VIA Bag Sorting'!AG3 | AH3: ='BBB'!AH3+'Bag Staging'!AH3+'Bag Staging Volumetric'!AH3+'FWD FSM'!AH3+'FWD Manual Pre Primary'!AH3+'FWD Manual Primary'!AH3+'FWD Primary with Scan'!AH3+'FWD Secondary'!AH3+'FWD Volumetric'!AH3+'IB'!AH3+'IB Volumetric'!AH3+'OB'!AH3+'OB Volumetric'!AH3+'OSC Bag Sorting'!AH3+'OSC Bag Sorting Volumetric'!AH3+'REV FSM'!AH3+'Rejection Primary with Scan'!AH3+'Rejection Secondary'!AH3+'Rev DC DC Primary Sorting'!AH3+'Rev Primary (FSM Rejections)'!AH3+'Rev Secondary Sorting'!AH3+'VIA Bag Sorting'!AH3 | AI3: ='BBB'!AI3+'Bag Staging'!AI3+'Bag Staging Volumetric'!AI3+'FWD FSM'!AI3+'FWD Manual Pre Primary'!AI3+'FWD Manual Primary'!AI3+'FWD Primary with Scan'!AI3+'FWD Secondary'!AI3+'FWD Volumetric'!AI3+'IB'!AI3+'IB Volumetric'!AI3+'OB'!AI3+'OB Volumetric'!AI3+'OSC Bag Sorting'!AI3+'OSC Bag Sorting Volumetric'!AI3+'REV FSM'!AI3+'Rejection Primary with Scan'!AI3+'Rejection Secondary'!AI3+'Rev DC DC Primary Sorting'!AI3+'Rev Primary (FSM Rejections)'!AI3+'Rev Secondary Sorting'!AI3+'VIA Bag Sorting'!AI3 | AJ3: ='BBB'!AJ3+'Bag Staging'!AJ3+'Bag Staging Volumetric'!AJ3+'FWD FSM'!AJ3+'FWD Manual Pre Primary'!AJ3+'FWD Manual Primary'!AJ3+'FWD Primary with Scan'!AJ3+'FWD Secondary'!AJ3+'FWD Volumetric'!AJ3+'IB'!AJ3+'IB Volumetric'!AJ3+'OB'!AJ3+'OB Volumetric'!AJ3+'OSC Bag Sorting'!AJ3+'OSC Bag Sorting Volumetric'!AJ3+'REV FSM'!AJ3+'Rejection Primary with Scan'!AJ3+'Rejection Secondary'!AJ3+'Rev DC DC Primary Sorting'!AJ3+'Rev Primary (FSM Rejections)'!AJ3+'Rev Secondary Sorting'!AJ3+'VIA Bag Sorting'!AJ3 | AK3: ='BBB'!AK3+'Bag Staging'!AK3+'Bag Staging Volumetric'!AK3+'FWD FSM'!AK3+'FWD Manual Pre Primary'!AK3+'FWD Manual Primary'!AK3+'FWD Primary with Scan'!AK3+'FWD Secondary'!AK3+'FWD Volumetric'!AK3+'IB'!AK3+'IB Volumetric'!AK3+'OB'!AK3+'OB Volumetric'!AK3+'OSC Bag Sorting'!AK3+'OSC Bag Sorting Volumetric'!AK3+'REV FSM'!AK3+'Rejection Primary with Scan'!AK3+'Rejection Secondary'!AK3+'Rev DC DC Primary Sorting'!AK3+'Rev Primary (FSM Rejections)'!AK3+'Rev Secondary Sorting'!AK3+'VIA Bag Sorting'!AK3 | ... BA3: ='BBB'!BA3+'Bag Staging'!BA3+'Bag Staging Volumetric'!BA3+'FWD FSM'!BA3+'FWD Manual Pre Primary'!BA3+'FWD Manual Primary'!BA3+'FWD Primary with Scan'!BA3+'FWD Secondary'!BA3+'FWD Volumetric'!BA3+'IB'!BA3+'IB Volumetric'!BA3+'OB'!BA3+'OB Volumetric'!BA3+'OSC Bag Sorting'!BA3+'OSC Bag Sorting Volumetric'!BA3+'REV FSM'!BA3+'Rejection Primary with Scan'!BA3+'Rejection Secondary'!BA3+'Rev DC DC Primary Sorting'!BA3+'Rev Primary (FSM Rejections)'!BA3+'Rev Secondary Sorting'!BA3+'VIA Bag Sorting'!BA3 | BB3: =SUM(AD3:BA3)
A4: AMD-AIR-NEW-SSC | B4: Forward Regular OSC | C4: 46096 | D4: 0 | E4: 0 | F4: 0 | G4: 0 | H4: 0 | I4: 0 | J4: 0 | K4: 0 | L4: 0 | M4: 0 | N4: 0 | O4: 0 | P4: 0 | Q4: 0 | R4: 371 | S4: 1 | T4: 0 | U4: 0 | V4: 0 | W4: 0 | X4: 0 | Y4: 0 | Z4: 0 | AA4: 0 | AB4: =SUM(D4:AA4) | AD4: ='BBB'!AD4+'Bag Staging'!AD4+'Bag Staging Volumetric'!AD4+'FWD FSM'!AD4+'FWD Manual Pre Primary'!AD4+'FWD Manual Primary'!AD4+'FWD Primary with Scan'!AD4+'FWD Secondary'!AD4+'FWD Volumetric'!AD4+'IB'!AD4+'IB Volumetric'!AD4+'OB'!AD4+'OB Volumetric'!AD4+'OSC Bag Sorting'!AD4+'OSC Bag Sorting Volumetric'!AD4+'REV FSM'!AD4+'Rejection Primary with Scan'!AD4+'Rejection Secondary'!AD4+'Rev DC DC Primary Sorting'!AD4+'Rev Primary (FSM Rejections)'!AD4+'Rev Secondary Sorting'!AD4+'VIA Bag Sorting'!AD4 | AE4: ='BBB'!AE4+'Bag Staging'!AE4+'Bag Staging Volumetric'!AE4+'FWD FSM'!AE4+'FWD Manual Pre Primary'!AE4+'FWD Manual Primary'!AE4+'FWD Primary with Scan'!AE4+'FWD Secondary'!AE4+'FWD Volumetric'!AE4+'IB'!AE4+'IB Volumetric'!AE4+'OB'!AE4+'OB Volumetric'!AE4+'OSC Bag Sorting'!AE4+'OSC Bag Sorting Volumetric'!AE4+'REV FSM'!AE4+'Rejection Primary with Scan'!AE4+'Rejection Secondary'!AE4+'Rev DC DC Primary Sorting'!AE4+'Rev Primary (FSM Rejections)'!AE4+'Rev Secondary Sorting'!AE4+'VIA Bag Sorting'!AE4 | AF4: ='BBB'!AF4+'Bag Staging'!AF4+'Bag Staging Volumetric'!AF4+'FWD FSM'!AF4+'FWD Manual Pre Primary'!AF4+'FWD Manual Primary'!AF4+'FWD Primary with Scan'!AF4+'FWD Secondary'!AF4+'FWD Volumetric'!AF4+'IB'!AF4+'IB Volumetric'!AF4+'OB'!AF4+'OB Volumetric'!AF4+'OSC Bag Sorting'!AF4+'OSC Bag Sorting Volumetric'!AF4+'REV FSM'!AF4+'Rejection Primary with Scan'!AF4+'Rejection Secondary'!AF4+'Rev DC DC Primary Sorting'!AF4+'Rev Primary (FSM Rejections)'!AF4+'Rev Secondary Sorting'!AF4+'VIA Bag Sorting'!AF4 | AG4: ='BBB'!AG4+'Bag Staging'!AG4+'Bag Staging Volumetric'!AG4+'FWD FSM'!AG4+'FWD Manual Pre Primary'!AG4+'FWD Manual Primary'!AG4+'FWD Primary with Scan'!AG4+'FWD Secondary'!AG4+'FWD Volumetric'!AG4+'IB'!AG4+'IB Volumetric'!AG4+'OB'!AG4+'OB Volumetric'!AG4+'OSC Bag Sorting'!AG4+'OSC Bag Sorting Volumetric'!AG4+'REV FSM'!AG4+'Rejection Primary with Scan'!AG4+'Rejection Secondary'!AG4+'Rev DC DC Primary Sorting'!AG4+'Rev Primary (FSM Rejections)'!AG4+'Rev Secondary Sorting'!AG4+'VIA Bag Sorting'!AG4 | AH4: ='BBB'!AH4+'Bag Staging'!AH4+'Bag Staging Volumetric'!AH4+'FWD FSM'!AH4+'FWD Manual Pre Primary'!AH4+'FWD Manual Primary'!AH4+'FWD Primary with Scan'!AH4+'FWD Secondary'!AH4+'FWD Volumetric'!AH4+'IB'!AH4+'IB Volumetric'!AH4+'OB'!AH4+'OB Volumetric'!AH4+'OSC Bag Sorting'!AH4+'OSC Bag Sorting Volumetric'!AH4+'REV FSM'!AH4+'Rejection Primary with Scan'!AH4+'Rejection Secondary'!AH4+'Rev DC DC Primary Sorting'!AH4+'Rev Primary (FSM Rejections)'!AH4+'Rev Secondary Sorting'!AH4+'VIA Bag Sorting'!AH4 | AI4: ='BBB'!AI4+'Bag Staging'!AI4+'Bag Staging Volumetric'!AI4+'FWD FSM'!AI4+'FWD Manual Pre Primary'!AI4+'FWD Manual Primary'!AI4+'FWD Primary with Scan'!AI4+'FWD Secondary'!AI4+'FWD Volumetric'!AI4+'IB'!AI4+'IB Volumetric'!AI4+'OB'!AI4+'OB Volumetric'!AI4+'OSC Bag Sorting'!AI4+'OSC Bag Sorting Volumetric'!AI4+'REV FSM'!AI4+'Rejection Primary with Scan'!AI4+'Rejection Secondary'!AI4+'Rev DC DC Primary Sorting'!AI4+'Rev Primary (FSM Rejections)'!AI4+'Rev Secondary Sorting'!AI4+'VIA Bag Sorting'!AI4 | AJ4: ='BBB'!AJ4+'Bag Staging'!AJ4+'Bag Staging Volumetric'!AJ4+'FWD FSM'!AJ4+'FWD Manual Pre Primary'!AJ4+'FWD Manual Primary'!AJ4+'FWD Primary with Scan'!AJ4+'FWD Secondary'!AJ4+'FWD Volumetric'!AJ4+'IB'!AJ4+'IB Volumetric'!AJ4+'OB'!AJ4+'OB Volumetric'!AJ4+'OSC Bag Sorting'!AJ4+'OSC Bag Sorting Volumetric'!AJ4+'REV FSM'!AJ4+'Rejection Primary with Scan'!AJ4+'Rejection Secondary'!AJ4+'Rev DC DC Primary Sorting'!AJ4+'Rev Primary (FSM Rejections)'!AJ4+'Rev Secondary Sorting'!AJ4+'VIA Bag Sorting'!AJ4 | AK4: ='BBB'!AK4+'Bag Staging'!AK4+'Bag Staging Volumetric'!AK4+'FWD FSM'!AK4+'FWD Manual Pre Primary'!AK4+'FWD Manual Primary'!AK4+'FWD Primary with Scan'!AK4+'FWD Secondary'!AK4+'FWD Volumetric'!AK4+'IB'!AK4+'IB Volumetric'!AK4+'OB'!AK4+'OB Volumetric'!AK4+'OSC Bag Sorting'!AK4+'OSC Bag Sorting Volumetric'!AK4+'REV FSM'!AK4+'Rejection Primary with Scan'!AK4+'Rejection Secondary'!AK4+'Rev DC DC Primary Sorting'!AK4+'Rev Primary (FSM Rejections)'!AK4+'Rev Secondary Sorting'!AK4+'VIA Bag Sorting'!AK4 | ... BA4: ='BBB'!BA4+'Bag Staging'!BA4+'Bag Staging Volumetric'!BA4+'FWD FSM'!BA4+'FWD Manual Pre Primary'!BA4+'FWD Manual Primary'!BA4+'FWD Primary with Scan'!BA4+'FWD Secondary'!BA4+'FWD Volumetric'!BA4+'IB'!BA4+'IB Volumetric'!BA4+'OB'!BA4+'OB Volumetric'!BA4+'OSC Bag Sorting'!BA4+'OSC Bag Sorting Volumetric'!BA4+'REV FSM'!BA4+'Rejection Primary with Scan'!BA4+'Rejection Secondary'!BA4+'Rev DC DC Primary Sorting'!BA4+'Rev Primary (FSM Rejections)'!BA4+'Rev Secondary Sorting'!BA4+'VIA Bag Sorting'!BA4 | BB4: =SUM(AD4:BA4)
A5: AMD-AIR-NEW-SSC | B5: Forward Regular OSC | C5: 46097 | D5: 0 | E5: 0 | F5: 0 | G5: 0 | H5: 0 | I5: 0 | J5: 0 | K5: 0 | L5: 0 | M5: 0 | N5: 0 | O5: 0 | P5: 0 | Q5: 0 | R5: 198 | S5: 1 | T5: 0 | U5: 0 | V5: 0 | W5: 0 | X5: 0 | Y5: 0 | Z5: 0 | AA5: 0 | AB5: =SUM(D5:AA5) | AD5: ='BBB'!AD5+'Bag Staging'!AD5+'Bag Staging Volumetric'!AD5+'FWD FSM'!AD5+'FWD Manual Pre Primary'!AD5+'FWD Manual Primary'!AD5+'FWD Primary with Scan'!AD5+'FWD Secondary'!AD5+'FWD Volumetric'!AD5+'IB'!AD5+'IB Volumetric'!AD5+'OB'!AD5+'OB Volumetric'!AD5+'OSC Bag Sorting'!AD5+'OSC Bag Sorting Volumetric'!AD5+'REV FSM'!AD5+'Rejection Primary with Scan'!AD5+'Rejection Secondary'!AD5+'Rev DC DC Primary Sorting'!AD5+'Rev Primary (FSM Rejections)'!AD5+'Rev Secondary Sorting'!AD5+'VIA Bag Sorting'!AD5 | AE5: ='BBB'!AE5+'Bag Staging'!AE5+'Bag Staging Volumetric'!AE5+'FWD FSM'!AE5+'FWD Manual Pre Primary'!AE5+'FWD Manual Primary'!AE5+'FWD Primary with Scan'!AE5+'FWD Secondary'!AE5+'FWD Volumetric'!AE5+'IB'!AE5+'IB Volumetric'!AE5+'OB'!AE5+'OB Volumetric'!AE5+'OSC Bag Sorting'!AE5+'OSC Bag Sorting Volumetric'!AE5+'REV FSM'!AE5+'Rejection Primary with Scan'!AE5+'Rejection Secondary'!AE5+'Rev DC DC Primary Sorting'!AE5+'Rev Primary (FSM Rejections)'!AE5+'Rev Secondary Sorting'!AE5+'VIA Bag Sorting'!AE5 | AF5: ='BBB'!AF5+'Bag Staging'!AF5+'Bag Staging Volumetric'!AF5+'FWD FSM'!AF5+'FWD Manual Pre Primary'!AF5+'FWD Manual Primary'!AF5+'FWD Primary with Scan'!AF5+'FWD Secondary'!AF5+'FWD Volumetric'!AF5+'IB'!AF5+'IB Volumetric'!AF5+'OB'!AF5+'OB Volumetric'!AF5+'OSC Bag Sorting'!AF5+'OSC Bag Sorting Volumetric'!AF5+'REV FSM'!AF5+'Rejection Primary with Scan'!AF5+'Rejection Secondary'!AF5+'Rev DC DC Primary Sorting'!AF5+'Rev Primary (FSM Rejections)'!AF5+'Rev Secondary Sorting'!AF5+'VIA Bag Sorting'!AF5 | AG5: ='BBB'!AG5+'Bag Staging'!AG5+'Bag Staging Volumetric'!AG5+'FWD FSM'!AG5+'FWD Manual Pre Primary'!AG5+'FWD Manual Primary'!AG5+'FWD Primary with Scan'!AG5+'FWD Secondary'!AG5+'FWD Volumetric'!AG5+'IB'!AG5+'IB Volumetric'!AG5+'OB'!AG5+'OB Volumetric'!AG5+'OSC Bag Sorting'!AG5+'OSC Bag Sorting Volumetric'!AG5+'REV FSM'!AG5+'Rejection Primary with Scan'!AG5+'Rejection Secondary'!AG5+'Rev DC DC Primary Sorting'!AG5+'Rev Primary (FSM Rejections)'!AG5+'Rev Secondary Sorting'!AG5+'VIA Bag Sorting'!AG5 | AH5: ='BBB'!AH5+'Bag Staging'!AH5+'Bag Staging Volumetric'!AH5+'FWD FSM'!AH5+'FWD Manual Pre Primary'!AH5+'FWD Manual Primary'!AH5+'FWD Primary with Scan'!AH5+'FWD Secondary'!AH5+'FWD Volumetric'!AH5+'IB'!AH5+'IB Volumetric'!AH5+'OB'!AH5+'OB Volumetric'!AH5+'OSC Bag Sorting'!AH5+'OSC Bag Sorting Volumetric'!AH5+'REV FSM'!AH5+'Rejection Primary with Scan'!AH5+'Rejection Secondary'!AH5+'Rev DC DC Primary Sorting'!AH5+'Rev Primary (FSM Rejections)'!AH5+'Rev Secondary Sorting'!AH5+'VIA Bag Sorting'!AH5 | AI5: ='BBB'!AI5+'Bag Staging'!AI5+'Bag Staging Volumetric'!AI5+'FWD FSM'!AI5+'FWD Manual Pre Primary'!AI5+'FWD Manual Primary'!AI5+'FWD Primary with Scan'!AI5+'FWD Secondary'!AI5+'FWD Volumetric'!AI5+'IB'!AI5+'IB Volumetric'!AI5+'OB'!AI5+'OB Volumetric'!AI5+'OSC Bag Sorting'!AI5+'OSC Bag Sorting Volumetric'!AI5+'REV FSM'!AI5+'Rejection Primary with Scan'!AI5+'Rejection Secondary'!AI5+'Rev DC DC Primary Sorting'!AI5+'Rev Primary (FSM Rejections)'!AI5+'Rev Secondary Sorting'!AI5+'VIA Bag Sorting'!AI5 | AJ5: ='BBB'!AJ5+'Bag Staging'!AJ5+'Bag Staging Volumetric'!AJ5+'FWD FSM'!AJ5+'FWD Manual Pre Primary'!AJ5+'FWD Manual Primary'!AJ5+'FWD Primary with Scan'!AJ5+'FWD Secondary'!AJ5+'FWD Volumetric'!AJ5+'IB'!AJ5+'IB Volumetric'!AJ5+'OB'!AJ5+'OB Volumetric'!AJ5+'OSC Bag Sorting'!AJ5+'OSC Bag Sorting Volumetric'!AJ5+'REV FSM'!AJ5+'Rejection Primary with Scan'!AJ5+'Rejection Secondary'!AJ5+'Rev DC DC Primary Sorting'!AJ5+'Rev Primary (FSM Rejections)'!AJ5+'Rev Secondary Sorting'!AJ5+'VIA Bag Sorting'!AJ5 | AK5: ='BBB'!AK5+'Bag Staging'!AK5+'Bag Staging Volumetric'!AK5+'FWD FSM'!AK5+'FWD Manual Pre Primary'!AK5+'FWD Manual Primary'!AK5+'FWD Primary with Scan'!AK5+'FWD Secondary'!AK5+'FWD Volumetric'!AK5+'IB'!AK5+'IB Volumetric'!AK5+'OB'!AK5+'OB Volumetric'!AK5+'OSC Bag Sorting'!AK5+'OSC Bag Sorting Volumetric'!AK5+'REV FSM'!AK5+'Rejection Primary with Scan'!AK5+'Rejection Secondary'!AK5+'Rev DC DC Primary Sorting'!AK5+'Rev Primary (FSM Rejections)'!AK5+'Rev Secondary Sorting'!AK5+'VIA Bag Sorting'!AK5 | ... BA5: ='BBB'!BA5+'Bag Staging'!BA5+'Bag Staging Volumetric'!BA5+'FWD FSM'!BA5+'FWD Manual Pre Primary'!BA5+'FWD Manual Primary'!BA5+'FWD Primary with Scan'!BA5+'FWD Secondary'!BA5+'FWD Volumetric'!BA5+'IB'!BA5+'IB Volumetric'!BA5+'OB'!BA5+'OB Volumetric'!BA5+'OSC Bag Sorting'!BA5+'OSC Bag Sorting Volumetric'!BA5+'REV FSM'!BA5+'Rejection Primary with Scan'!BA5+'Rejection Secondary'!BA5+'Rev DC DC Primary Sorting'!BA5+'Rev Primary (FSM Rejections)'!BA5+'Rev Secondary Sorting'!BA5+'VIA Bag Sorting'!BA5 | BB5: =SUM(AD5:BA5)
A6: AMD-AIR-NEW-SSC | B6: Forward Regular OSC | C6: 46100 | D6: 0 | E6: 0 | F6: 0 | G6: 0 | H6: 0 | I6: 0 | J6: 0 | K6: 0 | L6: 0 | M6: 0 | N6: 0 | O6: 0 | P6: 0 | Q6: 0 | R6: 306 | S6: 328 | T6: 0 | U6: 0 | V6: 0 | W6: 0 | X6: 0 | Y6: 0 | Z6: 0 | AA6: 0 | AB6: =SUM(D6:AA6) | AD6: ='BBB'!AD6+'Bag Staging'!AD6+'Bag Staging Volumetric'!AD6+'FWD FSM'!AD6+'FWD Manual Pre Primary'!AD6+'FWD Manual Primary'!AD6+'FWD Primary with Scan'!AD6+'FWD Secondary'!AD6+'FWD Volumetric'!AD6+'IB'!AD6+'IB Volumetric'!AD6+'OB'!AD6+'OB Volumetric'!AD6+'OSC Bag Sorting'!AD6+'OSC Bag Sorting Volumetric'!AD6+'REV FSM'!AD6+'Rejection Primary with Scan'!AD6+'Rejection Secondary'!AD6+'Rev DC DC Primary Sorting'!AD6+'Rev Primary (FSM Rejections)'!AD6+'Rev Secondary Sorting'!AD6+'VIA Bag Sorting'!AD6 | AE6: ='BBB'!AE6+'Bag Staging'!AE6+'Bag Staging Volumetric'!AE6+'FWD FSM'!AE6+'FWD Manual Pre Primary'!AE6+'FWD Manual Primary'!AE6+'FWD Primary with Scan'!AE6+'FWD Secondary'!AE6+'FWD Volumetric'!AE6+'IB'!AE6+'IB Volumetric'!AE6+'OB'!AE6+'OB Volumetric'!AE6+'OSC Bag Sorting'!AE6+'OSC Bag Sorting Volumetric'!AE6+'REV FSM'!AE6+'Rejection Primary with Scan'!AE6+'Rejection Secondary'!AE6+'Rev DC DC Primary Sorting'!AE6+'Rev Primary (FSM Rejections)'!AE6+'Rev Secondary Sorting'!AE6+'VIA Bag Sorting'!AE6 | AF6: ='BBB'!AF6+'Bag Staging'!AF6+'Bag Staging Volumetric'!AF6+'FWD FSM'!AF6+'FWD Manual Pre Primary'!AF6+'FWD Manual Primary'!AF6+'FWD Primary with Scan'!AF6+'FWD Secondary'!AF6+'FWD Volumetric'!AF6+'IB'!AF6+'IB Volumetric'!AF6+'OB'!AF6+'OB Volumetric'!AF6+'OSC Bag Sorting'!AF6+'OSC Bag Sorting Volumetric'!AF6+'REV FSM'!AF6+'Rejection Primary with Scan'!AF6+'Rejection Secondary'!AF6+'Rev DC DC Primary Sorting'!AF6+'Rev Primary (FSM Rejections)'!AF6+'Rev Secondary Sorting'!AF6+'VIA Bag Sorting'!AF6 | AG6: ='BBB'!AG6+'Bag Staging'!AG6+'Bag Staging Volumetric'!AG6+'FWD FSM'!AG6+'FWD Manual Pre Primary'!AG6+'FWD Manual Primary'!AG6+'FWD Primary with Scan'!AG6+'FWD Secondary'!AG6+'FWD Volumetric'!AG6+'IB'!AG6+'IB Volumetric'!AG6+'OB'!AG6+'OB Volumetric'!AG6+'OSC Bag Sorting'!AG6+'OSC Bag Sorting Volumetric'!AG6+'REV FSM'!AG6+'Rejection Primary with Scan'!AG6+'Rejection Secondary'!AG6+'Rev DC DC Primary Sorting'!AG6+'Rev Primary (FSM Rejections)'!AG6+'Rev Secondary Sorting'!AG6+'VIA Bag Sorting'!AG6 | AH6: ='BBB'!AH6+'Bag Staging'!AH6+'Bag Staging Volumetric'!AH6+'FWD FSM'!AH6+'FWD Manual Pre Primary'!AH6+'FWD Manual Primary'!AH6+'FWD Primary with Scan'!AH6+'FWD Secondary'!AH6+'FWD Volumetric'!AH6+'IB'!AH6+'IB Volumetric'!AH6+'OB'!AH6+'OB Volumetric'!AH6+'OSC Bag Sorting'!AH6+'OSC Bag Sorting Volumetric'!AH6+'REV FSM'!AH6+'Rejection Primary with Scan'!AH6+'Rejection Secondary'!AH6+'Rev DC DC Primary Sorting'!AH6+'Rev Primary (FSM Rejections)'!AH6+'Rev Secondary Sorting'!AH6+'VIA Bag Sorting'!AH6 | AI6: ='BBB'!AI6+'Bag Staging'!AI6+'Bag Staging Volumetric'!AI6+'FWD FSM'!AI6+'FWD Manual Pre Primary'!AI6+'FWD Manual Primary'!AI6+'FWD Primary with Scan'!AI6+'FWD Secondary'!AI6+'FWD Volumetric'!AI6+'IB'!AI6+'IB Volumetric'!AI6+'OB'!AI6+'OB Volumetric'!AI6+'OSC Bag Sorting'!AI6+'OSC Bag Sorting Volumetric'!AI6+'REV FSM'!AI6+'Rejection Primary with Scan'!AI6+'Rejection Secondary'!AI6+'Rev DC DC Primary Sorting'!AI6+'Rev Primary (FSM Rejections)'!AI6+'Rev Secondary Sorting'!AI6+'VIA Bag Sorting'!AI6 | AJ6: ='BBB'!AJ6+'Bag Staging'!AJ6+'Bag Staging Volumetric'!AJ6+'FWD FSM'!AJ6+'FWD Manual Pre Primary'!AJ6+'FWD Manual Primary'!AJ6+'FWD Primary with Scan'!AJ6+'FWD Secondary'!AJ6+'FWD Volumetric'!AJ6+'IB'!AJ6+'IB Volumetric'!AJ6+'OB'!AJ6+'OB Volumetric'!AJ6+'OSC Bag Sorting'!AJ6+'OSC Bag Sorting Volumetric'!AJ6+'REV FSM'!AJ6+'Rejection Primary with Scan'!AJ6+'Rejection Secondary'!AJ6+'Rev DC DC Primary Sorting'!AJ6+'Rev Primary (FSM Rejections)'!AJ6+'Rev Secondary Sorting'!AJ6+'VIA Bag Sorting'!AJ6 | AK6: ='BBB'!AK6+'Bag Staging'!AK6+'Bag Staging Volumetric'!AK6+'FWD FSM'!AK6+'FWD Manual Pre Primary'!AK6+'FWD Manual Primary'!AK6+'FWD Primary with Scan'!AK6+'FWD Secondary'!AK6+'FWD Volumetric'!AK6+'IB'!AK6+'IB Volumetric'!AK6+'OB'!AK6+'OB Volumetric'!AK6+'OSC Bag Sorting'!AK6+'OSC Bag Sorting Volumetric'!AK6+'REV FSM'!AK6+'Rejection Primary with Scan'!AK6+'Rejection Secondary'!AK6+'Rev DC DC Primary Sorting'!AK6+'Rev Primary (FSM Rejections)'!AK6+'Rev Secondary Sorting'!AK6+'VIA Bag Sorting'!AK6 | ... BA6: ='BBB'!BA6+'Bag Staging'!BA6+'Bag Staging Volumetric'!BA6+'FWD FSM'!BA6+'FWD Manual Pre Primary'!BA6+'FWD Manual Primary'!BA6+'FWD Primary with Scan'!BA6+'FWD Secondary'!BA6+'FWD Volumetric'!BA6+'IB'!BA6+'IB Volumetric'!BA6+'OB'!BA6+'OB Volumetric'!BA6+'OSC Bag Sorting'!BA6+'OSC Bag Sorting Volumetric'!BA6+'REV FSM'!BA6+'Rejection Primary with Scan'!BA6+'Rejection Secondary'!BA6+'Rev DC DC Primary Sorting'!BA6+'Rev Primary (FSM Rejections)'!BA6+'Rev Secondary Sorting'!BA6+'VIA Bag Sorting'!BA6 | BB6: =SUM(AD6:BA6)
A7: AMD-AIR-NEW-SSC | B7: Forward Regular OSC | C7: 46101 | D7: 0 | E7: 0 | F7: 0 | G7: 0 | H7: 0 | I7: 0 | J7: 0 | K7: 0 | L7: 0 | M7: 0 | N7: 0 | O7: 0 | P7: 0 | Q7: 0 | R7: 0 | S7: 376 | T7: 250 | U7: 0 | V7: 0 | W7: 0 | X7: 0 | Y7: 0 | Z7: 0 | AA7: 0 | AB7: =SUM(D7:AA7) | AD7: ='BBB'!AD7+'Bag Staging'!AD7+'Bag Staging Volumetric'!AD7+'FWD FSM'!AD7+'FWD Manual Pre Primary'!AD7+'FWD Manual Primary'!AD7+'FWD Primary with Scan'!AD7+'FWD Secondary'!AD7+'FWD Volumetric'!AD7+'IB'!AD7+'IB Volumetric'!AD7+'OB'!AD7+'OB Volumetric'!AD7+'OSC Bag Sorting'!AD7+'OSC Bag Sorting Volumetric'!AD7+'REV FSM'!AD7+'Rejection Primary with Scan'!AD7+'Rejection Secondary'!AD7+'Rev DC DC Primary Sorting'!AD7+'Rev Primary (FSM Rejections)'!AD7+'Rev Secondary Sorting'!AD7+'VIA Bag Sorting'!AD7 | AE7: ='BBB'!AE7+'Bag Staging'!AE7+'Bag Staging Volumetric'!AE7+'FWD FSM'!AE7+'FWD Manual Pre Primary'!AE7+'FWD Manual Primary'!AE7+'FWD Primary with Scan'!AE7+'FWD Secondary'!AE7+'FWD Volumetric'!AE7+'IB'!AE7+'IB Volumetric'!AE7+'OB'!AE7+'OB Volumetric'!AE7+'OSC Bag Sorting'!AE7+'OSC Bag Sorting Volumetric'!AE7+'REV FSM'!AE7+'Rejection Primary with Scan'!AE7+'Rejection Secondary'!AE7+'Rev DC DC Primary Sorting'!AE7+'Rev Primary (FSM Rejections)'!AE7+'Rev Secondary Sorting'!AE7+'VIA Bag Sorting'!AE7 | AF7: ='BBB'!AF7+'Bag Staging'!AF7+'Bag Staging Volumetric'!AF7+'FWD FSM'!AF7+'FWD Manual Pre Primary'!AF7+'FWD Manual Primary'!AF7+'FWD Primary with Scan'!AF7+'FWD Secondary'!AF7+'FWD Volumetric'!AF7+'IB'!AF7+'IB Volumetric'!AF7+'OB'!AF7+'OB Volumetric'!AF7+'OSC Bag Sorting'!AF7+'OSC Bag Sorting Volumetric'!AF7+'REV FSM'!AF7+'Rejection Primary with Scan'!AF7+'Rejection Secondary'!AF7+'Rev DC DC Primary Sorting'!AF7+'Rev Primary (FSM Rejections)'!AF7+'Rev Secondary Sorting'!AF7+'VIA Bag Sorting'!AF7 | AG7: ='BBB'!AG7+'Bag Staging'!AG7+'Bag Staging Volumetric'!AG7+'FWD FSM'!AG7+'FWD Manual Pre Primary'!AG7+'FWD Manual Primary'!AG7+'FWD Primary with Scan'!AG7+'FWD Secondary'!AG7+'FWD Volumetric'!AG7+'IB'!AG7+'IB Volumetric'!AG7+'OB'!AG7+'OB Volumetric'!AG7+'OSC Bag Sorting'!AG7+'OSC Bag Sorting Volumetric'!AG7+'REV FSM'!AG7+'Rejection Primary with Scan'!AG7+'Rejection Secondary'!AG7+'Rev DC DC Primary Sorting'!AG7+'Rev Primary (FSM Rejections)'!AG7+'Rev Secondary Sorting'!AG7+'VIA Bag Sorting'!AG7 | AH7: ='BBB'!AH7+'Bag Staging'!AH7+'Bag Staging Volumetric'!AH7+'FWD FSM'!AH7+'FWD Manual Pre Primary'!AH7+'FWD Manual Primary'!AH7+'FWD Primary with Scan'!AH7+'FWD Secondary'!AH7+'FWD Volumetric'!AH7+'IB'!AH7+'IB Volumetric'!AH7+'OB'!AH7+'OB Volumetric'!AH7+'OSC Bag Sorting'!AH7+'OSC Bag Sorting Volumetric'!AH7+'REV FSM'!AH7+'Rejection Primary with Scan'!AH7+'Rejection Secondary'!AH7+'Rev DC DC Primary Sorting'!AH7+'Rev Primary (FSM Rejections)'!AH7+'Rev Secondary Sorting'!AH7+'VIA Bag Sorting'!AH7 | AI7: ='BBB'!AI7+'Bag Staging'!AI7+'Bag Staging Volumetric'!AI7+'FWD FSM'!AI7+'FWD Manual Pre Primary'!AI7+'FWD Manual Primary'!AI7+'FWD Primary with Scan'!AI7+'FWD Secondary'!AI7+'FWD Volumetric'!AI7+'IB'!AI7+'IB Volumetric'!AI7+'OB'!AI7+'OB Volumetric'!AI7+'OSC Bag Sorting'!AI7+'OSC Bag Sorting Volumetric'!AI7+'REV FSM'!AI7+'Rejection Primary with Scan'!AI7+'Rejection Secondary'!AI7+'Rev DC DC Primary Sorting'!AI7+'Rev Primary (FSM Rejections)'!AI7+'Rev Secondary Sorting'!AI7+'VIA Bag Sorting'!AI7 | AJ7: ='BBB'!AJ7+'Bag Staging'!AJ7+'Bag Staging Volumetric'!AJ7+'FWD FSM'!AJ7+'FWD Manual Pre Primary'!AJ7+'FWD Manual Primary'!AJ7+'FWD Primary with Scan'!AJ7+'FWD Secondary'!AJ7+'FWD Volumetric'!AJ7+'IB'!AJ7+'IB Volumetric'!AJ7+'OB'!AJ7+'OB Volumetric'!AJ7+'OSC Bag Sorting'!AJ7+'OSC Bag Sorting Volumetric'!AJ7+'REV FSM'!AJ7+'Rejection Primary with Scan'!AJ7+'Rejection Secondary'!AJ7+'Rev DC DC Primary Sorting'!AJ7+'Rev Primary (FSM Rejections)'!AJ7+'Rev Secondary Sorting'!AJ7+'VIA Bag Sorting'!AJ7 | AK7: ='BBB'!AK7+'Bag Staging'!AK7+'Bag Staging Volumetric'!AK7+'FWD FSM'!AK7+'FWD Manual Pre Primary'!AK7+'FWD Manual Primary'!AK7+'FWD Primary with Scan'!AK7+'FWD Secondary'!AK7+'FWD Volumetric'!AK7+'IB'!AK7+'IB Volumetric'!AK7+'OB'!AK7+'OB Volumetric'!AK7+'OSC Bag Sorting'!AK7+'OSC Bag Sorting Volumetric'!AK7+'REV FSM'!AK7+'Rejection Primary with Scan'!AK7+'Rejection Secondary'!AK7+'Rev DC DC Primary Sorting'!AK7+'Rev Primary (FSM Rejections)'!AK7+'Rev Secondary Sorting'!AK7+'VIA Bag Sorting'!AK7 | ... BA7: ='BBB'!BA7+'Bag Staging'!BA7+'Bag Staging Volumetric'!BA7+'FWD FSM'!BA7+'FWD Manual Pre Primary'!BA7+'FWD Manual Primary'!BA7+'FWD Primary with Scan'!BA7+'FWD Secondary'!BA7+'FWD Volumetric'!BA7+'IB'!BA7+'IB Volumetric'!BA7+'OB'!BA7+'OB Volumetric'!BA7+'OSC Bag Sorting'!BA7+'OSC Bag Sorting Volumetric'!BA7+'REV FSM'!BA7+'Rejection Primary with Scan'!BA7+'Rejection Secondary'!BA7+'Rev DC DC Primary Sorting'!BA7+'Rev Primary (FSM Rejections)'!BA7+'Rev Secondary Sorting'!BA7+'VIA Bag Sorting'!BA7 | BB7: =SUM(AD7:BA7)
A8: AMD-AIR-NEW-SSC | B8: Forward Regular OSC | C8: 46102 | D8: 0 | E8: 0 | F8: 0 | G8: 0 | H8: 0 | I8: 0 | J8: 0 | K8: 0 | L8: 0 | M8: 0 | N8: 0 | O8: 0 | P8: 0 | Q8: 0 | R8: 55 | S8: 101 | T8: 0 | U8: 0 | V8: 0 | W8: 0 | X8: 0 | Y8: 0 | Z8: 0 | AA8: 0 | AB8: =SUM(D8:AA8) | AD8: ='BBB'!AD8+'Bag Staging'!AD8+'Bag Staging Volumetric'!AD8+'FWD FSM'!AD8+'FWD Manual Pre Primary'!AD8+'FWD Manual Primary'!AD8+'FWD Primary with Scan'!AD8+'FWD Secondary'!AD8+'FWD Volumetric'!AD8+'IB'!AD8+'IB Volumetric'!AD8+'OB'!AD8+'OB Volumetric'!AD8+'OSC Bag Sorting'!AD8+'OSC Bag Sorting Volumetric'!AD8+'REV FSM'!AD8+'Rejection Primary with Scan'!AD8+'Rejection Secondary'!AD8+'Rev DC DC Primary Sorting'!AD8+'Rev Primary (FSM Rejections)'!AD8+'Rev Secondary Sorting'!AD8+'VIA Bag Sorting'!AD8 | AE8: ='BBB'!AE8+'Bag Staging'!AE8+'Bag Staging Volumetric'!AE8+'FWD FSM'!AE8+'FWD Manual Pre Primary'!AE8+'FWD Manual Primary'!AE8+'FWD Primary with Scan'!AE8+'FWD Secondary'!AE8+'FWD Volumetric'!AE8+'IB'!AE8+'IB Volumetric'!AE8+'OB'!AE8+'OB Volumetric'!AE8+'OSC Bag Sorting'!AE8+'OSC Bag Sorting Volumetric'!AE8+'REV FSM'!AE8+'Rejection Primary with Scan'!AE8+'Rejection Secondary'!AE8+'Rev DC DC Primary Sorting'!AE8+'Rev Primary (FSM Rejections)'!AE8+'Rev Secondary Sorting'!AE8+'VIA Bag Sorting'!AE8 | AF8: ='BBB'!AF8+'Bag Staging'!AF8+'Bag Staging Volumetric'!AF8+'FWD FSM'!AF8+'FWD Manual Pre Primary'!AF8+'FWD Manual Primary'!AF8+'FWD Primary with Scan'!AF8+'FWD Secondary'!AF8+'FWD Volumetric'!AF8+'IB'!AF8+'IB Volumetric'!AF8+'OB'!AF8+'OB Volumetric'!AF8+'OSC Bag Sorting'!AF8+'OSC Bag Sorting Volumetric'!AF8+'REV FSM'!AF8+'Rejection Primary with Scan'!AF8+'Rejection Secondary'!AF8+'Rev DC DC Primary Sorting'!AF8+'Rev Primary (FSM Rejections)'!AF8+'Rev Secondary Sorting'!AF8+'VIA Bag Sorting'!AF8 | AG8: ='BBB'!AG8+'Bag Staging'!AG8+'Bag Staging Volumetric'!AG8+'FWD FSM'!AG8+'FWD Manual Pre Primary'!AG8+'FWD Manual Primary'!AG8+'FWD Primary with Scan'!AG8+'FWD Secondary'!AG8+'FWD Volumetric'!AG8+'IB'!AG8+'IB Volumetric'!AG8+'OB'!AG8+'OB Volumetric'!AG8+'OSC Bag Sorting'!AG8+'OSC Bag Sorting Volumetric'!AG8+'REV FSM'!AG8+'Rejection Primary with Scan'!AG8+'Rejection Secondary'!AG8+'Rev DC DC Primary Sorting'!AG8+'Rev Primary (FSM Rejections)'!AG8+'Rev Secondary Sorting'!AG8+'VIA Bag Sorting'!AG8 | AH8: ='BBB'!AH8+'Bag Staging'!AH8+'Bag Staging Volumetric'!AH8+'FWD FSM'!AH8+'FWD Manual Pre Primary'!AH8+'FWD Manual Primary'!AH8+'FWD Primary with Scan'!AH8+'FWD Secondary'!AH8+'FWD Volumetric'!AH8+'IB'!AH8+'IB Volumetric'!AH8+'OB'!AH8+'OB Volumetric'!AH8+'OSC Bag Sorting'!AH8+'OSC Bag Sorting Volumetric'!AH8+'REV FSM'!AH8+'Rejection Primary with Scan'!AH8+'Rejection Secondary'!AH8+'Rev DC DC Primary Sorting'!AH8+'Rev Primary (FSM Rejections)'!AH8+'Rev Secondary Sorting'!AH8+'VIA Bag Sorting'!AH8 | AI8: ='BBB'!AI8+'Bag Staging'!AI8+'Bag Staging Volumetric'!AI8+'FWD FSM'!AI8+'FWD Manual Pre Primary'!AI8+'FWD Manual Primary'!AI8+'FWD Primary with Scan'!AI8+'FWD Secondary'!AI8+'FWD Volumetric'!AI8+'IB'!AI8+'IB Volumetric'!AI8+'OB'!AI8+'OB Volumetric'!AI8+'OSC Bag Sorting'!AI8+'OSC Bag Sorting Volumetric'!AI8+'REV FSM'!AI8+'Rejection Primary with Scan'!AI8+'Rejection Secondary'!AI8+'Rev DC DC Primary Sorting'!AI8+'Rev Primary (FSM Rejections)'!AI8+'Rev Secondary Sorting'!AI8+'VIA Bag Sorting'!AI8 | AJ8: ='BBB'!AJ8+'Bag Staging'!AJ8+'Bag Staging Volumetric'!AJ8+'FWD FSM'!AJ8+'FWD Manual Pre Primary'!AJ8+'FWD Manual Primary'!AJ8+'FWD Primary with Scan'!AJ8+'FWD Secondary'!AJ8+'FWD Volumetric'!AJ8+'IB'!AJ8+'IB Volumetric'!AJ8+'OB'!AJ8+'OB Volumetric'!AJ8+'OSC Bag Sorting'!AJ8+'OSC Bag Sorting Volumetric'!AJ8+'REV FSM'!AJ8+'Rejection Primary with Scan'!AJ8+'Rejection Secondary'!AJ8+'Rev DC DC Primary Sorting'!AJ8+'Rev Primary (FSM Rejections)'!AJ8+'Rev Secondary Sorting'!AJ8+'VIA Bag Sorting'!AJ8 | AK8: ='BBB'!AK8+'Bag Staging'!AK8+'Bag Staging Volumetric'!AK8+'FWD FSM'!AK8+'FWD Manual Pre Primary'!AK8+'FWD Manual Primary'!AK8+'FWD Primary with Scan'!AK8+'FWD Secondary'!AK8+'FWD Volumetric'!AK8+'IB'!AK8+'IB Volumetric'!AK8+'OB'!AK8+'OB Volumetric'!AK8+'OSC Bag Sorting'!AK8+'OSC Bag Sorting Volumetric'!AK8+'REV FSM'!AK8+'Rejection Primary with Scan'!AK8+'Rejection Secondary'!AK8+'Rev DC DC Primary Sorting'!AK8+'Rev Primary (FSM Rejections)'!AK8+'Rev Secondary Sorting'!AK8+'VIA Bag Sorting'!AK8 | ... BA8: ='BBB'!BA8+'Bag Staging'!BA8+'Bag Staging Volumetric'!BA8+'FWD FSM'!BA8+'FWD Manual Pre Primary'!BA8+'FWD Manual Primary'!BA8+'FWD Primary with Scan'!BA8+'FWD Secondary'!BA8+'FWD Volumetric'!BA8+'IB'!BA8+'IB Volumetric'!BA8+'OB'!BA8+'OB Volumetric'!BA8+'OSC Bag Sorting'!BA8+'OSC Bag Sorting Volumetric'!BA8+'REV FSM'!BA8+'Rejection Primary with Scan'!BA8+'Rejection Secondary'!BA8+'Rev DC DC Primary Sorting'!BA8+'Rev Primary (FSM Rejections)'!BA8+'Rev Secondary Sorting'!BA8+'VIA Bag Sorting'!BA8 | BB8: =SUM(AD8:BA8)
A9: AMD-AIR-NEW-SSC | B9: Forward Regular OSC | C9: 46103 | D9: 0 | E9: 0 | F9: 0 | G9: 0 | H9: 0 | I9: 0 | J9: 0 | K9: 0 | L9: 0 | M9: 0 | N9: 0 | O9: 0 | P9: 0 | Q9: 0 | R9: 191 | S9: 0 | T9: 9 | U9: 0 | V9: 0 | W9: 0 | X9: 0 | Y9: 0 | Z9: 0 | AA9: 0 | AB9: =SUM(D9:AA9) | AD9: ='BBB'!AD9+'Bag Staging'!AD9+'Bag Staging Volumetric'!AD9+'FWD FSM'!AD9+'FWD Manual Pre Primary'!AD9+'FWD Manual Primary'!AD9+'FWD Primary with Scan'!AD9+'FWD Secondary'!AD9+'FWD Volumetric'!AD9+'IB'!AD9+'IB Volumetric'!AD9+'OB'!AD9+'OB Volumetric'!AD9+'OSC Bag Sorting'!AD9+'OSC Bag Sorting Volumetric'!AD9+'REV FSM'!AD9+'Rejection Primary with Scan'!AD9+'Rejection Secondary'!AD9+'Rev DC DC Primary Sorting'!AD9+'Rev Primary (FSM Rejections)'!AD9+'Rev Secondary Sorting'!AD9+'VIA Bag Sorting'!AD9 | AE9: ='BBB'!AE9+'Bag Staging'!AE9+'Bag Staging Volumetric'!AE9+'FWD FSM'!AE9+'FWD Manual Pre Primary'!AE9+'FWD Manual Primary'!AE9+'FWD Primary with Scan'!AE9+'FWD Secondary'!AE9+'FWD Volumetric'!AE9+'IB'!AE9+'IB Volumetric'!AE9+'OB'!AE9+'OB Volumetric'!AE9+'OSC Bag Sorting'!AE9+'OSC Bag Sorting Volumetric'!AE9+'REV FSM'!AE9+'Rejection Primary with Scan'!AE9+'Rejection Secondary'!AE9+'Rev DC DC Primary Sorting'!AE9+'Rev Primary (FSM Rejections)'!AE9+'Rev Secondary Sorting'!AE9+'VIA Bag Sorting'!AE9 | AF9: ='BBB'!AF9+'Bag Staging'!AF9+'Bag Staging Volumetric'!AF9+'FWD FSM'!AF9+'FWD Manual Pre Primary'!AF9+'FWD Manual Primary'!AF9+'FWD Primary with Scan'!AF9+'FWD Secondary'!AF9+'FWD Volumetric'!AF9+'IB'!AF9+'IB Volumetric'!AF9+'OB'!AF9+'OB Volumetric'!AF9+'OSC Bag Sorting'!AF9+'OSC Bag Sorting Volumetric'!AF9+'REV FSM'!AF9+'Rejection Primary with Scan'!AF9+'Rejection Secondary'!AF9+'Rev DC DC Primary Sorting'!AF9+'Rev Primary (FSM Rejections)'!AF9+'Rev Secondary Sorting'!AF9+'VIA Bag Sorting'!AF9 | AG9: ='BBB'!AG9+'Bag Staging'!AG9+'Bag Staging Volumetric'!AG9+'FWD FSM'!AG9+'FWD Manual Pre Primary'!AG9+'FWD Manual Primary'!AG9+'FWD Primary with Scan'!AG9+'FWD Secondary'!AG9+'FWD Volumetric'!AG9+'IB'!AG9+'IB Volumetric'!AG9+'OB'!AG9+'OB Volumetric'!AG9+'OSC Bag Sorting'!AG9+'OSC Bag Sorting Volumetric'!AG9+'REV FSM'!AG9+'Rejection Primary with Scan'!AG9+'Rejection Secondary'!AG9+'Rev DC DC Primary Sorting'!AG9+'Rev Primary (FSM Rejections)'!AG9+'Rev Secondary Sorting'!AG9+'VIA Bag Sorting'!AG9 | AH9: ='BBB'!AH9+'Bag Staging'!AH9+'Bag Staging Volumetric'!AH9+'FWD FSM'!AH9+'FWD Manual Pre Primary'!AH9+'FWD Manual Primary'!AH9+'FWD Primary with Scan'!AH9+'FWD Secondary'!AH9+'FWD Volumetric'!AH9+'IB'!AH9+'IB Volumetric'!AH9+'OB'!AH9+'OB Volumetric'!AH9+'OSC Bag Sorting'!AH9+'OSC Bag Sorting Volumetric'!AH9+'REV FSM'!AH9+'Rejection Primary with Scan'!AH9+'Rejection Secondary'!AH9+'Rev DC DC Primary Sorting'!AH9+'Rev Primary (FSM Rejections)'!AH9+'Rev Secondary Sorting'!AH9+'VIA Bag Sorting'!AH9 | AI9: ='BBB'!AI9+'Bag Staging'!AI9+'Bag Staging Volumetric'!AI9+'FWD FSM'!AI9+'FWD Manual Pre Primary'!AI9+'FWD Manual Primary'!AI9+'FWD Primary with Scan'!AI9+'FWD Secondary'!AI9+'FWD Volumetric'!AI9+'IB'!AI9+'IB Volumetric'!AI9+'OB'!AI9+'OB Volumetric'!AI9+'OSC Bag Sorting'!AI9+'OSC Bag Sorting Volumetric'!AI9+'REV FSM'!AI9+'Rejection Primary with Scan'!AI9+'Rejection Secondary'!AI9+'Rev DC DC Primary Sorting'!AI9+'Rev Primary (FSM Rejections)'!AI9+'Rev Secondary Sorting'!AI9+'VIA Bag Sorting'!AI9 | AJ9: ='BBB'!AJ9+'Bag Staging'!AJ9+'Bag Staging Volumetric'!AJ9+'FWD FSM'!AJ9+'FWD Manual Pre Primary'!AJ9+'FWD Manual Primary'!AJ9+'FWD Primary with Scan'!AJ9+'FWD Secondary'!AJ9+'FWD Volumetric'!AJ9+'IB'!AJ9+'IB Volumetric'!AJ9+'OB'!AJ9+'OB Volumetric'!AJ9+'OSC Bag Sorting'!AJ9+'OSC Bag Sorting Volumetric'!AJ9+'REV FSM'!AJ9+'Rejection Primary with Scan'!AJ9+'Rejection Secondary'!AJ9+'Rev DC DC Primary Sorting'!AJ9+'Rev Primary (FSM Rejections)'!AJ9+'Rev Secondary Sorting'!AJ9+'VIA Bag Sorting'!AJ9 | AK9: ='BBB'!AK9+'Bag Staging'!AK9+'Bag Staging Volumetric'!AK9+'FWD FSM'!AK9+'FWD Manual Pre Primary'!AK9+'FWD Manual Primary'!AK9+'FWD Primary with Scan'!AK9+'FWD Secondary'!AK9+'FWD Volumetric'!AK9+'IB'!AK9+'IB Volumetric'!AK9+'OB'!AK9+'OB Volumetric'!AK9+'OSC Bag Sorting'!AK9+'OSC Bag Sorting Volumetric'!AK9+'REV FSM'!AK9+'Rejection Primary with Scan'!AK9+'Rejection Secondary'!AK9+'Rev DC DC Primary Sorting'!AK9+'Rev Primary (FSM Rejections)'!AK9+'Rev Secondary Sorting'!AK9+'VIA Bag Sorting'!AK9 | ... BA9: ='BBB'!BA9+'Bag Staging'!BA9+'Bag Staging Volumetric'!BA9+'FWD FSM'!BA9+'FWD Manual Pre Primary'!BA9+'FWD Manual Primary'!BA9+'FWD Primary with Scan'!BA9+'FWD Secondary'!BA9+'FWD Volumetric'!BA9+'IB'!BA9+'IB Volumetric'!BA9+'OB'!BA9+'OB Volumetric'!BA9+'OSC Bag Sorting'!BA9+'OSC Bag Sorting Volumetric'!BA9+'REV FSM'!BA9+'Rejection Primary with Scan'!BA9+'Rejection Secondary'!BA9+'Rev DC DC Primary Sorting'!BA9+'Rev Primary (FSM Rejections)'!BA9+'Rev Secondary Sorting'!BA9+'VIA Bag Sorting'!BA9 | BB9: =SUM(AD9:BA9)
A10: AMD-AIR-NEW-SSC | B10: Forward Regular OSC | C10: 46104 | D10: 0 | E10: 0 | F10: 0 | G10: 0 | H10: 0 | I10: 0 | J10: 0 | K10: 0 | L10: 0 | M10: 0 | N10: 0 | O10: 0 | P10: 0 | Q10: 0 | R10: 212 | S10: 0 | T10: 0 | U10: 0 | V10: 0 | W10: 0 | X10: 0 | Y10: 0 | Z10: 0 | AA10: 0 | AB10: =SUM(D10:AA10) | AD10: ='BBB'!AD10+'Bag Staging'!AD10+'Bag Staging Volumetric'!AD10+'FWD FSM'!AD10+'FWD Manual Pre Primary'!AD10+'FWD Manual Primary'!AD10+'FWD Primary with Scan'!AD10+'FWD Secondary'!AD10+'FWD Volumetric'!AD10+'IB'!AD10+'IB Volumetric'!AD10+'OB'!AD10+'OB Volumetric'!AD10+'OSC Bag Sorting'!AD10+'OSC Bag Sorting Volumetric'!AD10+'REV FSM'!AD10+'Rejection Primary with Scan'!AD10+'Rejection Secondary'!AD10+'Rev DC DC Primary Sorting'!AD10+'Rev Primary (FSM Rejections)'!AD10+'Rev Secondary Sorting'!AD10+'VIA Bag Sorting'!AD10 | AE10: ='BBB'!AE10+'Bag Staging'!AE10+'Bag Staging Volumetric'!AE10+'FWD FSM'!AE10+'FWD Manual Pre Primary'!AE10+'FWD Manual Primary'!AE10+'FWD Primary with Scan'!AE10+'FWD Secondary'!AE10+'FWD Volumetric'!AE10+'IB'!AE10+'IB Volumetric'!AE10+'OB'!AE10+'OB Volumetric'!AE10+'OSC Bag Sorting'!AE10+'OSC Bag Sorting Volumetric'!AE10+'REV FSM'!AE10+'Rejection Primary with Scan'!AE10+'Rejection Secondary'!AE10+'Rev DC DC Primary Sorting'!AE10+'Rev Primary (FSM Rejections)'!AE10+'Rev Secondary Sorting'!AE10+'VIA Bag Sorting'!AE10 | AF10: ='BBB'!AF10+'Bag Staging'!AF10+'Bag Staging Volumetric'!AF10+'FWD FSM'!AF10+'FWD Manual Pre Primary'!AF10+'FWD Manual Primary'!AF10+'FWD Primary with Scan'!AF10+'FWD Secondary'!AF10+'FWD Volumetric'!AF10+'IB'!AF10+'IB Volumetric'!AF10+'OB'!AF10+'OB Volumetric'!AF10+'OSC Bag Sorting'!AF10+'OSC Bag Sorting Volumetric'!AF10+'REV FSM'!AF10+'Rejection Primary with Scan'!AF10+'Rejection Secondary'!AF10+'Rev DC DC Primary Sorting'!AF10+'Rev Primary (FSM Rejections)'!AF10+'Rev Secondary Sorting'!AF10+'VIA Bag Sorting'!AF10 | AG10: ='BBB'!AG10+'Bag Staging'!AG10+'Bag Staging Volumetric'!AG10+'FWD FSM'!AG10+'FWD Manual Pre Primary'!AG10+'FWD Manual Primary'!AG10+'FWD Primary with Scan'!AG10+'FWD Secondary'!AG10+'FWD Volumetric'!AG10+'IB'!AG10+'IB Volumetric'!AG10+'OB'!AG10+'OB Volumetric'!AG10+'OSC Bag Sorting'!AG10+'OSC Bag Sorting Volumetric'!AG10+'REV FSM'!AG10+'Rejection Primary with Scan'!AG10+'Rejection Secondary'!AG10+'Rev DC DC Primary Sorting'!AG10+'Rev Primary (FSM Rejections)'!AG10+'Rev Secondary Sorting'!AG10+'VIA Bag Sorting'!AG10 | AH10: ='BBB'!AH10+'Bag Staging'!AH10+'Bag Staging Volumetric'!AH10+'FWD FSM'!AH10+'FWD Manual Pre Primary'!AH10+'FWD Manual Primary'!AH10+'FWD Primary with Scan'!AH10+'FWD Secondary'!AH10+'FWD Volumetric'!AH10+'IB'!AH10+'IB Volumetric'!AH10+'OB'!AH10+'OB Volumetric'!AH10+'OSC Bag Sorting'!AH10+'OSC Bag Sorting Volumetric'!AH10+'REV FSM'!AH10+'Rejection Primary with Scan'!AH10+'Rejection Secondary'!AH10+'Rev DC DC Primary Sorting'!AH10+'Rev Primary (FSM Rejections)'!AH10+'Rev Secondary Sorting'!AH10+'VIA Bag Sorting'!AH10 | AI10: ='BBB'!AI10+'Bag Staging'!AI10+'Bag Staging Volumetric'!AI10+'FWD FSM'!AI10+'FWD Manual Pre Primary'!AI10+'FWD Manual Primary'!AI10+'FWD Primary with Scan'!AI10+'FWD Secondary'!AI10+'FWD Volumetric'!AI10+'IB'!AI10+'IB Volumetric'!AI10+'OB'!AI10+'OB Volumetric'!AI10+'OSC Bag Sorting'!AI10+'OSC Bag Sorting Volumetric'!AI10+'REV FSM'!AI10+'Rejection Primary with Scan'!AI10+'Rejection Secondary'!AI10+'Rev DC DC Primary Sorting'!AI10+'Rev Primary (FSM Rejections)'!AI10+'Rev Secondary Sorting'!AI10+'VIA Bag Sorting'!AI10 | AJ10: ='BBB'!AJ10+'Bag Staging'!AJ10+'Bag Staging Volumetric'!AJ10+'FWD FSM'!AJ10+'FWD Manual Pre Primary'!AJ10+'FWD Manual Primary'!AJ10+'FWD Primary with Scan'!AJ10+'FWD Secondary'!AJ10+'FWD Volumetric'!AJ10+'IB'!AJ10+'IB Volumetric'!AJ10+'OB'!AJ10+'OB Volumetric'!AJ10+'OSC Bag Sorting'!AJ10+'OSC Bag Sorting Volumetric'!AJ10+'REV FSM'!AJ10+'Rejection Primary with Scan'!AJ10+'Rejection Secondary'!AJ10+'Rev DC DC Primary Sorting'!AJ10+'Rev Primary (FSM Rejections)'!AJ10+'Rev Secondary Sorting'!AJ10+'VIA Bag Sorting'!AJ10 | AK10: ='BBB'!AK10+'Bag Staging'!AK10+'Bag Staging Volumetric'!AK10+'FWD FSM'!AK10+'FWD Manual Pre Primary'!AK10+'FWD Manual Primary'!AK10+'FWD Primary with Scan'!AK10+'FWD Secondary'!AK10+'FWD Volumetric'!AK10+'IB'!AK10+'IB Volumetric'!AK10+'OB'!AK10+'OB Volumetric'!AK10+'OSC Bag Sorting'!AK10+'OSC Bag Sorting Volumetric'!AK10+'REV FSM'!AK10+'Rejection Primary with Scan'!AK10+'Rejection Secondary'!AK10+'Rev DC DC Primary Sorting'!AK10+'Rev Primary (FSM Rejections)'!AK10+'Rev Secondary Sorting'!AK10+'VIA Bag Sorting'!AK10 | ... BA10: ='BBB'!BA10+'Bag Staging'!BA10+'Bag Staging Volumetric'!BA10+'FWD FSM'!BA10+'FWD Manual Pre Primary'!BA10+'FWD Manual Primary'!BA10+'FWD Primary with Scan'!BA10+'FWD Secondary'!BA10+'FWD Volumetric'!BA10+'IB'!BA10+'IB Volumetric'!BA10+'OB'!BA10+'OB Volumetric'!BA10+'OSC Bag Sorting'!BA10+'OSC Bag Sorting Volumetric'!BA10+'REV FSM'!BA10+'Rejection Primary with Scan'!BA10+'Rejection Secondary'!BA10+'Rev DC DC Primary Sorting'!BA10+'Rev Primary (FSM Rejections)'!BA10+'Rev Secondary Sorting'!BA10+'VIA Bag Sorting'!BA10 | BB10: =SUM(AD10:BA10)
A11: AMD-EXPR | B11: DSC Manual | C11: 46089 | D11: 0 | E11: 0 | F11: 0 | G11: 49 | H11: 364 | I11: 155 | J11: 99 | K11: 79 | L11: 0 | M11: 0 | N11: 0 | O11: 0 | P11: 0 | Q11: 0 | R11: 0 | S11: 477 | T11: 0 | U11: 282 | V11: 380 | W11: 395 | X11: 636 | Y11: 663 | Z11: 0 | AA11: 0 | AB11: =SUM(D11:AA11) | AD11: ='BBB'!AD11+'Bag Staging'!AD11+'Bag Staging Volumetric'!AD11+'FWD FSM'!AD11+'FWD Manual Pre Primary'!AD11+'FWD Manual Primary'!AD11+'FWD Primary with Scan'!AD11+'FWD Secondary'!AD11+'FWD Volumetric'!AD11+'IB'!AD11+'IB Volumetric'!AD11+'OB'!AD11+'OB Volumetric'!AD11+'OSC Bag Sorting'!AD11+'OSC Bag Sorting Volumetric'!AD11+'REV FSM'!AD11+'Rejection Primary with Scan'!AD11+'Rejection Secondary'!AD11+'Rev DC DC Primary Sorting'!AD11+'Rev Primary (FSM Rejections)'!AD11+'Rev Secondary Sorting'!AD11+'VIA Bag Sorting'!AD11 | AE11: ='BBB'!AE11+'Bag Staging'!AE11+'Bag Staging Volumetric'!AE11+'FWD FSM'!AE11+'FWD Manual Pre Primary'!AE11+'FWD Manual Primary'!AE11+'FWD Primary with Scan'!AE11+'FWD Secondary'!AE11+'FWD Volumetric'!AE11+'IB'!AE11+'IB Volumetric'!AE11+'OB'!AE11+'OB Volumetric'!AE11+'OSC Bag Sorting'!AE11+'OSC Bag Sorting Volumetric'!AE11+'REV FSM'!AE11+'Rejection Primary with Scan'!AE11+'Rejection Secondary'!AE11+'Rev DC DC Primary Sorting'!AE11+'Rev Primary (FSM Rejections)'!AE11+'Rev Secondary Sorting'!AE11+'VIA Bag Sorting'!AE11 | AF11: ='BBB'!AF11+'Bag Staging'!AF11+'Bag Staging Volumetric'!AF11+'FWD FSM'!AF11+'FWD Manual Pre Primary'!AF11+'FWD Manual Primary'!AF11+'FWD Primary with Scan'!AF11+'FWD Secondary'!AF11+'FWD Volumetric'!AF11+'IB'!AF11+'IB Volumetric'!AF11+'OB'!AF11+'OB Volumetric'!AF11+'OSC Bag Sorting'!AF11+'OSC Bag Sorting Volumetric'!AF11+'REV FSM'!AF11+'Rejection Primary with Scan'!AF11+'Rejection Secondary'!AF11+'Rev DC DC Primary Sorting'!AF11+'Rev Primary (FSM Rejections)'!AF11+'Rev Secondary Sorting'!AF11+'VIA Bag Sorting'!AF11 | AG11: ='BBB'!AG11+'Bag Staging'!AG11+'Bag Staging Volumetric'!AG11+'FWD FSM'!AG11+'FWD Manual Pre Primary'!AG11+'FWD Manual Primary'!AG11+'FWD Primary with Scan'!AG11+'FWD Secondary'!AG11+'FWD Volumetric'!AG11+'IB'!AG11+'IB Volumetric'!AG11+'OB'!AG11+'OB Volumetric'!AG11+'OSC Bag Sorting'!AG11+'OSC Bag Sorting Volumetric'!AG11+'REV FSM'!AG11+'Rejection Primary with Scan'!AG11+'Rejection Secondary'!AG11+'Rev DC DC Primary Sorting'!AG11+'Rev Primary (FSM Rejections)'!AG11+'Rev Secondary Sorting'!AG11+'VIA Bag Sorting'!AG11 | AH11: ='BBB'!AH11+'Bag Staging'!AH11+'Bag Staging Volumetric'!AH11+'FWD FSM'!AH11+'FWD Manual Pre Primary'!AH11+'FWD Manual Primary'!AH11+'FWD Primary with Scan'!AH11+'FWD Secondary'!AH11+'FWD Volumetric'!AH11+'IB'!AH11+'IB Volumetric'!AH11+'OB'!AH11+'OB Volumetric'!AH11+'OSC Bag Sorting'!AH11+'OSC Bag Sorting Volumetric'!AH11+'REV FSM'!AH11+'Rejection Primary with Scan'!AH11+'Rejection Secondary'!AH11+'Rev DC DC Primary Sorting'!AH11+'Rev Primary (FSM Rejections)'!AH11+'Rev Secondary Sorting'!AH11+'VIA Bag Sorting'!AH11 | AI11: ='BBB'!AI11+'Bag Staging'!AI11+'Bag Staging Volumetric'!AI11+'FWD FSM'!AI11+'FWD Manual Pre Primary'!AI11+'FWD Manual Primary'!AI11+'FWD Primary with Scan'!AI11+'FWD Secondary'!AI11+'FWD Volumetric'!AI11+'IB'!AI11+'IB Volumetric'!AI11+'OB'!AI11+'OB Volumetric'!AI11+'OSC Bag Sorting'!AI11+'OSC Bag Sorting Volumetric'!AI11+'REV FSM'!AI11+'Rejection Primary with Scan'!AI11+'Rejection Secondary'!AI11+'Rev DC DC Primary Sorting'!AI11+'Rev Primary (FSM Rejections)'!AI11+'Rev Secondary Sorting'!AI11+'VIA Bag Sorting'!AI11 | AJ11: ='BBB'!AJ11+'Bag Staging'!AJ11+'Bag Staging Volumetric'!AJ11+'FWD FSM'!AJ11+'FWD Manual Pre Primary'!AJ11+'FWD Manual Primary'!AJ11+'FWD Primary with Scan'!AJ11+'FWD Secondary'!AJ11+'FWD Volumetric'!AJ11+'IB'!AJ11+'IB Volumetric'!AJ11+'OB'!AJ11+'OB Volumetric'!AJ11+'OSC Bag Sorting'!AJ11+'OSC Bag Sorting Volumetric'!AJ11+'REV FSM'!AJ11+'Rejection Primary with Scan'!AJ11+'Rejection Secondary'!AJ11+'Rev DC DC Primary Sorting'!AJ11+'Rev Primary (FSM Rejections)'!AJ11+'Rev Secondary Sorting'!AJ11+'VIA Bag Sorting'!AJ11 | AK11: ='BBB'!AK11+'Bag Staging'!AK11+'Bag Staging Volumetric'!AK11+'FWD FSM'!AK11+'FWD Manual Pre Primary'!AK11+'FWD Manual Primary'!AK11+'FWD Primary with Scan'!AK11+'FWD Secondary'!AK11+'FWD Volumetric'!AK11+'IB'!AK11+'IB Volumetric'!AK11+'OB'!AK11+'OB Volumetric'!AK11+'OSC Bag Sorting'!AK11+'OSC Bag Sorting Volumetric'!AK11+'REV FSM'!AK11+'Rejection Primary with Scan'!AK11+'Rejection Secondary'!AK11+'Rev DC DC Primary Sorting'!AK11+'Rev Primary (FSM Rejections)'!AK11+'Rev Secondary Sorting'!AK11+'VIA Bag Sorting'!AK11 | ... BA11: ='BBB'!BA11+'Bag Staging'!BA11+'Bag Staging Volumetric'!BA11+'FWD FSM'!BA11+'FWD Manual Pre Primary'!BA11+'FWD Manual Primary'!BA11+'FWD Primary with Scan'!BA11+'FWD Secondary'!BA11+'FWD Volumetric'!BA11+'IB'!BA11+'IB Volumetric'!BA11+'OB'!BA11+'OB Volumetric'!BA11+'OSC Bag Sorting'!BA11+'OSC Bag Sorting Volumetric'!BA11+'REV FSM'!BA11+'Rejection Primary with Scan'!BA11+'Rejection Secondary'!BA11+'Rev DC DC Primary Sorting'!BA11+'Rev Primary (FSM Rejections)'!BA11+'Rev Secondary Sorting'!BA11+'VIA Bag Sorting'!BA11 | BB11: =SUM(AD11:BA11)
A12: AMD-EXPR | B12: DSC Manual | C12: 46090 | D12: 0 | E12: 0 | F12: 0 | G12: 0 | H12: 0 | I12: 215 | J12: 315 | K12: 0 | L12: 0 | M12: 0 | N12: 0 | O12: 0 | P12: 0 | Q12: 0 | R12: 0 | S12: 0 | T12: 467 | U12: 0 | V12: 352 | W12: 328 | X12: 456 | Y12: 467 | Z12: 472 | AA12: 0 | AB12: =SUM(D12:AA12) | AD12: ='BBB'!AD12+'Bag Staging'!AD12+'Bag Staging Volumetric'!AD12+'FWD FSM'!AD12+'FWD Manual Pre Primary'!AD12+'FWD Manual Primary'!AD12+'FWD Primary with Scan'!AD12+'FWD Secondary'!AD12+'FWD Volumetric'!AD12+'IB'!AD12+'IB Volumetric'!AD12+'OB'!AD12+'OB Volumetric'!AD12+'OSC Bag Sorting'!AD12+'OSC Bag Sorting Volumetric'!AD12+'REV FSM'!AD12+'Rejection Primary with Scan'!AD12+'Rejection Secondary'!AD12+'Rev DC DC Primary Sorting'!AD12+'Rev Primary (FSM Rejections)'!AD12+'Rev Secondary Sorting'!AD12+'VIA Bag Sorting'!AD12 | AE12: ='BBB'!AE12+'Bag Staging'!AE12+'Bag Staging Volumetric'!AE12+'FWD FSM'!AE12+'FWD Manual Pre Primary'!AE12+'FWD Manual Primary'!AE12+'FWD Primary with Scan'!AE12+'FWD Secondary'!AE12+'FWD Volumetric'!AE12+'IB'!AE12+'IB Volumetric'!AE12+'OB'!AE12+'OB Volumetric'!AE12+'OSC Bag Sorting'!AE12+'OSC Bag Sorting Volumetric'!AE12+'REV FSM'!AE12+'Rejection Primary with Scan'!AE12+'Rejection Secondary'!AE12+'Rev DC DC Primary Sorting'!AE12+'Rev Primary (FSM Rejections)'!AE12+'Rev Secondary Sorting'!AE12+'VIA Bag Sorting'!AE12 | AF12: ='BBB'!AF12+'Bag Staging'!AF12+'Bag Staging Volumetric'!AF12+'FWD FSM'!AF12+'FWD Manual Pre Primary'!AF12+'FWD Manual Primary'!AF12+'FWD Primary with Scan'!AF12+'FWD Secondary'!AF12+'FWD Volumetric'!AF12+'IB'!AF12+'IB Volumetric'!AF12+'OB'!AF12+'OB Volumetric'!AF12+'OSC Bag Sorting'!AF12+'OSC Bag Sorting Volumetric'!AF12+'REV FSM'!AF12+'Rejection Primary with Scan'!AF12+'Rejection Secondary'!AF12+'Rev DC DC Primary Sorting'!AF12+'Rev Primary (FSM Rejections)'!AF12+'Rev Secondary Sorting'!AF12+'VIA Bag Sorting'!AF12 | AG12: ='BBB'!AG12+'Bag Staging'!AG12+'Bag Staging Volumetric'!AG12+'FWD FSM'!AG12+'FWD Manual Pre Primary'!AG12+'FWD Manual Primary'!AG12+'FWD Primary with Scan'!AG12+'FWD Secondary'!AG12+'FWD Volumetric'!AG12+'IB'!AG12+'IB Volumetric'!AG12+'OB'!AG12+'OB Volumetric'!AG12+'OSC Bag Sorting'!AG12+'OSC Bag Sorting Volumetric'!AG12+'REV FSM'!AG12+'Rejection Primary with Scan'!AG12+'Rejection Secondary'!AG12+'Rev DC DC Primary Sorting'!AG12+'Rev Primary (FSM Rejections)'!AG12+'Rev Secondary Sorting'!AG12+'VIA Bag Sorting'!AG12 | AH12: ='BBB'!AH12+'Bag Staging'!AH12+'Bag Staging Volumetric'!AH12+'FWD FSM'!AH12+'FWD Manual Pre Primary'!AH12+'FWD Manual Primary'!AH12+'FWD Primary with Scan'!AH12+'FWD Secondary'!AH12+'FWD Volumetric'!AH12+'IB'!AH12+'IB Volumetric'!AH12+'OB'!AH12+'OB Volumetric'!AH12+'OSC Bag Sorting'!AH12+'OSC Bag Sorting Volumetric'!AH12+'REV FSM'!AH12+'Rejection Primary with Scan'!AH12+'Rejection Secondary'!AH12+'Rev DC DC Primary Sorting'!AH12+'Rev Primary (FSM Rejections)'!AH12+'Rev Secondary Sorting'!AH12+'VIA Bag Sorting'!AH12 | AI12: ='BBB'!AI12+'Bag Staging'!AI12+'Bag Staging Volumetric'!AI12+'FWD FSM'!AI12+'FWD Manual Pre Primary'!AI12+'FWD Manual Primary'!AI12+'FWD Primary with Scan'!AI12+'FWD Secondary'!AI12+'FWD Volumetric'!AI12+'IB'!AI12+'IB Volumetric'!AI12+'OB'!AI12+'OB Volumetric'!AI12+'OSC Bag Sorting'!AI12+'OSC Bag Sorting Volumetric'!AI12+'REV FSM'!AI12+'Rejection Primary with Scan'!AI12+'Rejection Secondary'!AI12+'Rev DC DC Primary Sorting'!AI12+'Rev Primary (FSM Rejections)'!AI12+'Rev Secondary Sorting'!AI12+'VIA Bag Sorting'!AI12 | AJ12: ='BBB'!AJ12+'Bag Staging'!AJ12+'Bag Staging Volumetric'!AJ12+'FWD FSM'!AJ12+'FWD Manual Pre Primary'!AJ12+'FWD Manual Primary'!AJ12+'FWD Primary with Scan'!AJ12+'FWD Secondary'!AJ12+'FWD Volumetric'!AJ12+'IB'!AJ12+'IB Volumetric'!AJ12+'OB'!AJ12+'OB Volumetric'!AJ12+'OSC Bag Sorting'!AJ12+'OSC Bag Sorting Volumetric'!AJ12+'REV FSM'!AJ12+'Rejection Primary with Scan'!AJ12+'Rejection Secondary'!AJ12+'Rev DC DC Primary Sorting'!AJ12+'Rev Primary (FSM Rejections)'!AJ12+'Rev Secondary Sorting'!AJ12+'VIA Bag Sorting'!AJ12 | AK12: ='BBB'!AK12+'Bag Staging'!AK12+'Bag Staging Volumetric'!AK12+'FWD FSM'!AK12+'FWD Manual Pre Primary'!AK12+'FWD Manual Primary'!AK12+'FWD Primary with Scan'!AK12+'FWD Secondary'!AK12+'FWD Volumetric'!AK12+'IB'!AK12+'IB Volumetric'!AK12+'OB'!AK12+'OB Volumetric'!AK12+'OSC Bag Sorting'!AK12+'OSC Bag Sorting Volumetric'!AK12+'REV FSM'!AK12+'Rejection Primary with Scan'!AK12+'Rejection Secondary'!AK12+'Rev DC DC Primary Sorting'!AK12+'Rev Primary (FSM Rejections)'!AK12+'Rev Secondary Sorting'!AK12+'VIA Bag Sorting'!AK12 | ... BA12: ='BBB'!BA12+'Bag Staging'!BA12+'Bag Staging Volumetric'!BA12+'FWD FSM'!BA12+'FWD Manual Pre Primary'!BA12+'FWD Manual Primary'!BA12+'FWD Primary with Scan'!BA12+'FWD Secondary'!BA12+'FWD Volumetric'!BA12+'IB'!BA12+'IB Volumetric'!BA12+'OB'!BA12+'OB Volumetric'!BA12+'OSC Bag Sorting'!BA12+'OSC Bag Sorting Volumetric'!BA12+'REV FSM'!BA12+'Rejection Primary with Scan'!BA12+'Rejection Secondary'!BA12+'Rev DC DC Primary Sorting'!BA12+'Rev Primary (FSM Rejections)'!BA12+'Rev Secondary Sorting'!BA12+'VIA Bag Sorting'!BA12 | BB12: =SUM(AD12:BA12)
